<?xml version="1.0" ?>
<!-- =================================================================================== -->
<!-- |    This document was autogenerated by xacro from /home/zxj/ros2_ws/src/go2w_auto_explore/urdf/go2w_real.urdf.xacro | -->
<!-- |    EDITING THIS FILE BY HAND IS NOT RECOMMENDED                                 | -->
<!-- =================================================================================== -->
<!--
  GO2W URDF for real robot (no Gazebo plugins).
  Uses local const.xacro and meshes so the package is standalone.
  Only provides TF tree: base -> body -> legs/sensors
-->
<robot name="go2w">
  <!-- Base -->
  <link name="base"/>
  <!-- Body -->
  <link name="body">
    <inertial>
      <origin rpy="0 0 0" xyz="0.021112 0.0 -0.005366"/>
      <mass value="6.921"/>
      <inertia ixx="0.02448" ixy="0.00012166" ixz="0.0014849" iyy="0.098077" iyz="-3.12e-05" izz="0.107"/>
    </inertial>
    <visual>
      <origin rpy="0 0 0" xyz="0 0 0"/>
      <geometry>
        <mesh filename="file:///home/zxj/ros2_ws/install/go2w_auto_explore/share/go2w_auto_explore/meshes/base.dae"/>
      </geometry>
    </visual>
  </link>
  <joint name="body_joint" type="fixed">
    <parent link="base"/>
    <child link="body"/>
  </joint>
  <!-- Head Upper -->
  <link name="Head_upper">
    <inertial>
      <origin rpy="0 0 0" xyz="0.0 0.0 0.0"/>
      <mass value="0.001"/>
      <inertia ixx="9.6e-06" ixy="0.0" ixz="0.0" iyy="9.6e-06" iyz="0.0" izz="9.6e-06"/>
    </inertial>
  </link>
  <joint dont_collapse="true" name="Head_upper_joint" type="fixed">
    <origin rpy="0 0 0" xyz="0.285 0 0.01"/>
    <parent link="body"/>
    <child link="Head_upper"/>
  </joint>
  <!-- Head Lower -->
  <link name="Head_lower">
    <inertial>
      <origin rpy="0 0 0" xyz="0.0 0.0 0.0"/>
      <mass value="0.001"/>
      <inertia ixx="9.6e-06" ixy="0.0" ixz="0.0" iyy="9.6e-06" iyz="0.0" izz="9.6e-06"/>
    </inertial>
  </link>
  <joint dont_collapse="true" name="Head_lower_joint" type="fixed">
    <origin rpy="0 0 0" xyz="0.008 0 -0.07"/>
    <parent link="Head_upper"/>
    <child link="Head_lower"/>
  </joint>
  <link name="FL_hip">
    <inertial>
      <origin rpy="0 0 0" xyz="-0.0054 0.00194 -0.000105"/>
      <mass value="0.678"/>
      <inertia ixx="0.00048" ixy="-3.01e-06" ixz="1.11e-06" iyy="0.000884" iyz="-1.42e-06" izz="0.000596"/>
    </inertial>
    <visual>
      <origin rpy="0 0 0" xyz="0 0 0"/>
      <geometry>
        <mesh filename="file:///home/zxj/ros2_ws/install/go2w_auto_explore/share/go2w_auto_explore/meshes/hip.dae"/>
      </geometry>
    </visual>
  </link>
  <joint name="FL_hip_joint" type="fixed">
    <origin rpy="0.0 0 0" xyz="0.1934 0.0465 0.0"/>
    <parent link="body"/>
    <child link="FL_hip"/>
  </joint>
  <link name="FL_thigh">
    <inertial>
      <origin rpy="0 0 0" xyz="-0.00374 -0.0223 -0.0327"/>
      <mass value="1.152"/>
      <inertia ixx="0.00584" ixy="8.72e-05" ixz="-0.000289" iyy="0.0058" iyz="0.000808" izz="0.00103"/>
    </inertial>
    <visual>
      <origin rpy="0 0 0" xyz="0 0 0"/>
      <geometry>
        <mesh filename="file:///home/zxj/ros2_ws/install/go2w_auto_explore/share/go2w_auto_explore/meshes/thigh.dae" scale="1 1 1"/>
      </geometry>
    </visual>
  </link>
  <joint name="FL_thigh_joint" type="fixed">
    <origin rpy="0 1.0143535137176514 0" xyz="0 0.0955 0.0"/>
    <parent link="FL_hip"/>
    <child link="FL_thigh"/>
  </joint>
  <link name="FL_calf">
    <inertial>
      <origin rpy="0 0 0" xyz="0.00548 -0.000975 -0.115"/>
      <mass value="0.154"/>
      <inertia ixx="0.00108" ixy="3.4e-07" ixz="1.72e-05" iyy="0.0011" iyz="8.28e-06" izz="3.29e-05"/>
    </inertial>
    <visual>
      <origin rpy="0 0 0" xyz="0 0 0"/>
      <geometry>
        <mesh filename="file:///home/zxj/ros2_ws/install/go2w_auto_explore/share/go2w_auto_explore/meshes/calf.stl"/>
      </geometry>
      <material name="">
        <color rgba="1 1 1 1"/>
      </material>
    </visual>
  </link>
  <joint name="FL_calf_joint" type="fixed">
    <origin rpy="0 -2.0287070274353027 0" xyz="0.0 0.0 -0.213"/>
    <parent link="FL_thigh"/>
    <child link="FL_calf"/>
  </joint>
  <link name="FL_foot">
    <inertial>
      <origin rpy="0 0 0" xyz="0.0 0.06 0.0"/>
      <mass value="0.52"/>
      <inertia ixx="0.0007" ixy="0.0" ixz="0.0" iyy="0.0012" iyz="0.0" izz="0.0007"/>
    </inertial>
    <visual>
      <origin rpy="0 0 0" xyz="0 0 0"/>
      <geometry>
        <mesh filename="file:///home/zxj/ros2_ws/install/go2w_auto_explore/share/go2w_auto_explore/meshes/left_wheel.dae"/>
      </geometry>
    </visual>
  </link>
  <joint name="FL_foot_joint" type="continuous">
    <origin rpy="0 0 0" xyz="0.0 0.0 -0.2264"/>
    <parent link="FL_calf"/>
    <child link="FL_foot"/>
    <axis xyz="0 1 0"/>
  </joint>
  <link name="FR_hip">
    <inertial>
      <origin rpy="0 0 0" xyz="-0.0054 -0.00194 -0.000105"/>
      <mass value="0.678"/>
      <inertia ixx="0.00048" ixy="3.01e-06" ixz="1.11e-06" iyy="0.000884" iyz="1.42e-06" izz="0.000596"/>
    </inertial>
    <visual>
      <origin rpy="3.141592653589793 0 0" xyz="0 0 0"/>
      <geometry>
        <mesh filename="file:///home/zxj/ros2_ws/install/go2w_auto_explore/share/go2w_auto_explore/meshes/hip.dae"/>
      </geometry>
    </visual>
  </link>
  <joint name="FR_hip_joint" type="fixed">
    <origin rpy="0.0 0 0" xyz="0.1934 -0.0465 0.0"/>
    <parent link="body"/>
    <child link="FR_hip"/>
  </joint>
  <link name="FR_thigh">
    <inertial>
      <origin rpy="0 0 0" xyz="-0.00374 0.0223 -0.0327"/>
      <mass value="1.152"/>
      <inertia ixx="0.00584" ixy="-8.72e-05" ixz="-0.000289" iyy="0.0058" iyz="-0.000808" izz="0.00103"/>
    </inertial>
    <visual>
      <origin rpy="0 0 0" xyz="0 0 0"/>
      <geometry>
        <mesh filename="file:///home/zxj/ros2_ws/install/go2w_auto_explore/share/go2w_auto_explore/meshes/thigh_mirror.dae" scale="1 1 1"/>
      </geometry>
    </visual>
  </link>
  <joint name="FR_thigh_joint" type="fixed">
    <origin rpy="0 1.0143535137176514 0" xyz="0 -0.0955 0.0"/>
    <parent link="FR_hip"/>
    <child link="FR_thigh"/>
  </joint>
  <link name="FR_calf">
    <inertial>
      <origin rpy="0 0 0" xyz="0.00548 0.000975 -0.115"/>
      <mass value="0.154"/>
      <inertia ixx="0.00108" ixy="-3.4e-07" ixz="1.72e-05" iyy="0.0011" iyz="-8.28e-06" izz="3.29e-05"/>
    </inertial>
    <visual>
      <origin rpy="0 0 0" xyz="0 0 0"/>
      <geometry>
        <mesh filename="file:///home/zxj/ros2_ws/install/go2w_auto_explore/share/go2w_auto_explore/meshes/calf_mirror.stl"/>
      </geometry>
      <material name="">
        <color rgba="1 1 1 1"/>
      </material>
    </visual>
  </link>
  <joint name="FR_calf_joint" type="fixed">
    <origin rpy="0 -2.0287070274353027 0" xyz="0.0 -0.0 -0.213"/>
    <parent link="FR_thigh"/>
    <child link="FR_calf"/>
  </joint>
  <link name="FR_foot">
    <inertial>
      <origin rpy="0 0 0" xyz="0.0 0.06 0.0"/>
      <mass value="0.52"/>
      <inertia ixx="0.0007" ixy="0.0" ixz="0.0" iyy="0.0012" iyz="0.0" izz="0.0007"/>
    </inertial>
    <visual>
      <origin rpy="0 0 0" xyz="0 0 0"/>
      <geometry>
        <mesh filename="file:///home/zxj/ros2_ws/install/go2w_auto_explore/share/go2w_auto_explore/meshes/right_wheel.dae"/>
      </geometry>
    </visual>
  </link>
  <joint name="FR_foot_joint" type="continuous">
    <origin rpy="0 0 0" xyz="0.0 -0.0 -0.2264"/>
    <parent link="FR_calf"/>
    <child link="FR_foot"/>
    <axis xyz="0 1 0"/>
  </joint>
  <link name="RL_hip">
    <inertial>
      <origin rpy="0 0 0" xyz="0.0054 0.00194 -0.000105"/>
      <mass value="0.678"/>
      <inertia ixx="0.00048" ixy="3.01e-06" ixz="-1.11e-06" iyy="0.000884" iyz="-1.42e-06" izz="0.000596"/>
    </inertial>
    <visual>
      <origin rpy="0 3.141592653589793 0" xyz="0 0 0"/>
      <geometry>
        <mesh filename="file:///home/zxj/ros2_ws/install/go2w_auto_explore/share/go2w_auto_explore/meshes/hip.dae"/>
      </geometry>
    </visual>
  </link>
  <joint name="RL_hip_joint" type="fixed">
    <origin rpy="0.0 0 0" xyz="-0.1934 0.0465 0.0"/>
    <parent link="body"/>
    <child link="RL_hip"/>
  </joint>
  <link name="RL_thigh">
    <inertial>
      <origin rpy="0 0 0" xyz="-0.00374 -0.0223 -0.0327"/>
      <mass value="1.152"/>
      <inertia ixx="0.00584" ixy="8.72e-05" ixz="-0.000289" iyy="0.0058" iyz="0.000808" izz="0.00103"/>
    </inertial>
    <visual>
      <origin rpy="0 0 0" xyz="0 0 0"/>
      <geometry>
        <mesh filename="file:///home/zxj/ros2_ws/install/go2w_auto_explore/share/go2w_auto_explore/meshes/thigh.dae" scale="1 1 1"/>
      </geometry>
    </visual>
  </link>
  <joint name="RL_thigh_joint" type="fixed">
    <origin rpy="0 1.0143535137176514 0" xyz="0 0.0955 0.0"/>
    <parent link="RL_hip"/>
    <child link="RL_thigh"/>
  </joint>
  <link name="RL_calf">
    <inertial>
      <origin rpy="0 0 0" xyz="0.00548 -0.000975 -0.115"/>
      <mass value="0.154"/>
      <inertia ixx="0.00108" ixy="3.4e-07" ixz="1.72e-05" iyy="0.0011" iyz="8.28e-06" izz="3.29e-05"/>
    </inertial>
    <visual>
      <origin rpy="0 0 0" xyz="0 0 0"/>
      <geometry>
        <mesh filename="file:///home/zxj/ros2_ws/install/go2w_auto_explore/share/go2w_auto_explore/meshes/calf.stl"/>
      </geometry>
      <material name="">
        <color rgba="1 1 1 1"/>
      </material>
    </visual>
  </link>
  <joint name="RL_calf_joint" type="fixed">
    <origin rpy="0 -2.0287070274353027 0" xyz="0.0 0.0 -0.213"/>
    <parent link="RL_thigh"/>
    <child link="RL_calf"/>
  </joint>
  <link name="RL_foot">
    <inertial>
      <origin rpy="0 0 0" xyz="0.0 0.06 0.0"/>
      <mass value="0.52"/>
      <inertia ixx="0.0007" ixy="0.0" ixz="0.0" iyy="0.0012" iyz="0.0" izz="0.0007"/>
    </inertial>
    <visual>
      <origin rpy="0 0 0" xyz="0 0 0"/>
      <geometry>
        <mesh filename="file:///home/zxj/ros2_ws/install/go2w_auto_explore/share/go2w_auto_explore/meshes/left_wheel.dae"/>
      </geometry>
    </visual>
  </link>
  <joint name="RL_foot_joint" type="continuous">
    <origin rpy="0 0 0" xyz="0.0 0.0 -0.2264"/>
    <parent link="RL_calf"/>
    <child link="RL_foot"/>
    <axis xyz="0 1 0"/>
  </joint>
  <link name="RR_hip">
    <inertial>
      <origin rpy="0 0 0" xyz="0.0054 -0.00194 -0.000105"/>
      <mass value="0.678"/>
      <inertia ixx="0.00048" ixy="-3.01e-06" ixz="-1.11e-06" iyy="0.000884" iyz="1.42e-06" izz="0.000596"/>
    </inertial>
    <visual>
      <origin rpy="3.141592653589793 3.141592653589793 0" xyz="0 0 0"/>
      <geometry>
        <mesh filename="file:///home/zxj/ros2_ws/install/go2w_auto_explore/share/go2w_auto_explore/meshes/hip.dae"/>
      </geometry>
    </visual>
  </link>
  <joint name="RR_hip_joint" type="fixed">
    <origin rpy="0.0 0 0" xyz="-0.1934 -0.0465 0.0"/>
    <parent link="body"/>
    <child link="RR_hip"/>
  </joint>
  <link name="RR_thigh">
    <inertial>
      <origin rpy="0 0 0" xyz="-0.00374 0.0223 -0.0327"/>
      <mass value="1.152"/>
      <inertia ixx="0.00584" ixy="-8.72e-05" ixz="-0.000289" iyy="0.0058" iyz="-0.000808" izz="0.00103"/>
    </inertial>
    <visual>
      <origin rpy="0 0 0" xyz="0 0 0"/>
      <geometry>
        <mesh filename="file:///home/zxj/ros2_ws/install/go2w_auto_explore/share/go2w_auto_explore/meshes/thigh_mirror.dae" scale="1 1 1"/>
      </geometry>
    </visual>
  </link>
  <joint name="RR_thigh_joint" type="fixed">
    <origin rpy="0 1.0143535137176514 0" xyz="0 -0.0955 0.0"/>
    <parent link="RR_hip"/>
    <child link="RR_thigh"/>
  </joint>
  <link name="RR_calf">
    <inertial>
      <origin rpy="0 0 0" xyz="0.00548 0.000975 -0.115"/>
      <mass value="0.154"/>
      <inertia ixx="0.00108" ixy="-3.4e-07" ixz="1.72e-05" iyy="0.0011" iyz="-8.28e-06" izz="3.29e-05"/>
    </inertial>
    <visual>
      <origin rpy="0 0 0" xyz="0 0 0"/>
      <geometry>
        <mesh filename="file:///home/zxj/ros2_ws/install/go2w_auto_explore/share/go2w_auto_explore/meshes/calf_mirror.stl"/>
      </geometry>
      <material name="">
        <color rgba="1 1 1 1"/>
      </material>
    </visual>
  </link>
  <joint name="RR_calf_joint" type="fixed">
    <origin rpy="0 -2.0287070274353027 0" xyz="0.0 -0.0 -0.213"/>
    <parent link="RR_thigh"/>
    <child link="RR_calf"/>
  </joint>
  <link name="RR_foot">
    <inertial>
      <origin rpy="0 0 0" xyz="0.0 0.06 0.0"/>
      <mass value="0.52"/>
      <inertia ixx="0.0007" ixy="0.0" ixz="0.0" iyy="0.0012" iyz="0.0" izz="0.0007"/>
    </inertial>
    <visual>
      <origin rpy="0 0 0" xyz="0 0 0"/>
      <geometry>
        <mesh filename="file:///home/zxj/ros2_ws/install/go2w_auto_explore/share/go2w_auto_explore/meshes/right_wheel.dae"/>
      </geometry>
    </visual>
  </link>
  <joint name="RR_foot_joint" type="continuous">
    <origin rpy="0 0 0" xyz="0.0 -0.0 -0.2264"/>
    <parent link="RR_calf"/>
    <child link="RR_foot"/>
    <axis xyz="0 1 0"/>
  </joint>
  <!-- IMU link -->
  <link name="imu">
    <inertial>
      <origin rpy="0 0 0" xyz="0 0 0"/>
      <mass value="0.001"/>
      <inertia ixx="1e-6" ixy="0" ixz="0" iyy="1e-6" iyz="0" izz="1e-6"/>
    </inertial>
  </link>
  <joint name="imu_joint" type="fixed">
    <origin rpy="0 0 0" xyz="-0.02557 0 0.04232"/>
    <parent link="body"/>
    <child link="imu"/>
  </joint>
  <!-- LiDAR link -->
  <link name="lidar">
    <inertial>
      <origin rpy="0 0 0" xyz="0 0 0"/>
      <mass value="0.001"/>
      <inertia ixx="1e-6" ixy="0" ixz="0" iyy="1e-6" iyz="0" izz="1e-6"/>
    </inertial>
  </link>
  <joint name="lidar_joint" type="fixed">
    <origin rpy="0 0 0" xyz="0.28945 0 -0.046825"/>
    <parent link="body"/>
    <child link="lidar"/>
  </joint>
  <!-- Camera link -->
  <link name="camera">
    <inertial>
      <origin rpy="0 0 0" xyz="0 0 0"/>
      <mass value="0.001"/>
      <inertia ixx="1e-6" ixy="0" ixz="0" iyy="1e-6" iyz="0" izz="1e-6"/>
    </inertial>
  </link>
  <joint name="camera_joint" type="fixed">
    <origin rpy="0 0 0" xyz="0.325 0 0.043"/>
    <parent link="body"/>
    <child link="camera"/>
  </joint>
  <!-- No Gazebo plugins - all sensing/actuation via go2w_bridge node -->
</robot>
